<!--An inchworm xml environment in MuJoCo-->

<mujoco model="2d_inchworm">
  <option integrator="RK4" timestep="0.01"/>
  <worldbody>
    <!-- Ground -->
    <body name="ground" pos="0 0 0">
      <geom type="plane" size="5 5 0.1" rgba="0.8 0.8 0.8 1"/>
    </body>

    <!-- Segment 1: Left Foot -->
    <body name="left_foot" pos="-3 0 1">
      <geom type="box" size="1 0.2 0.2" rgba="0.8 0 0 1"/>
      <joint name="hc_joint" type="hinge" pos="3 0 0" axis="0 1 0"/>
      <joint name="hsx_joint" type="slide" pos="3 0 0" axis="1 0 0"/>
      <joint name="hsy_joint" type="slide" pos="3 0 0" axis="0 0 1"/>

      <!-- Segment 2: Left Middle -->
      <body name="left_middle" pos="2 0 0">
        <geom type="box" size="1 0.2 0.2" rgba="0 0.8 0 1"/>
        <joint name="left_joint" type="hinge" pos="-1 0 0" axis="0 1 0"/>

        <!-- Segment 3: Right Middle -->
        <body name="right_middle" pos="2 0 0">
          <geom type="box" size="1 0.2 0.2" rgba="0 0 0.8 1"/>
          <joint name="middle_joint" type="hinge" pos="-1 0 0" axis="0 1 0"/>

          <!-- Segment 4: Right Foot -->
          <body name="right_foot" pos="2 0 0">
            <geom type="box" size="1 0.2 0.2" rgba="0.8 0.8 0 1"/>
            <joint name="right_joint" type="hinge" pos="-1 0 0" axis="0 1 0"/>
          </body>

        </body>
      </body>
    </body>
  </worldbody>
</mujoco>
